<mujoco model="xarm_gripper_model">
  <asset>
    <mesh name="xarm_gripper_base_link" file="meshes/gripper/xarm/base_link.stl" />
    <mesh name="xarm_gripper_left_outer_knuckle" file="meshes/gripper/xarm/left_outer_knuckle.stl" />
    <mesh name="xarm_gripper_left_finger" file="meshes/gripper/xarm/left_finger.stl" />
    <mesh name="xarm_gripper_left_inner_knuckle" file="meshes/gripper/xarm/left_inner_knuckle.stl" />
    <mesh name="xarm_gripper_right_outer_knuckle" file="meshes/gripper/xarm/right_outer_knuckle.stl" />
    <mesh name="xarm_gripper_right_finger" file="meshes/gripper/xarm/right_finger.stl" />
    <mesh name="xarm_gripper_right_inner_knuckle" file="meshes/gripper/xarm/right_inner_knuckle.stl" />
  </asset>

  <worldbody>
    <body name="xarm_gripper_base_link" pos="0 0 0">
      <site name="ft_frame" pos="0 0 0" size="0.01 0.01 0.01" rgba="1 0 0 1" type="sphere" group="1" />
      <body name="eef" pos="0 0 0.172" quat="0.707105 0 0 -0.707105">
        <site name="grip_site" pos="0 0 0" size="0.01 0.01 0.01" rgba="1 0 0 0.5" type="sphere" group="1" />
        <site name="ee_x" pos="0.1 0 0" size="0.005 .1" quat="0.707105 0 0.707108 0" rgba="1 0 0 0" type="cylinder" group="1" />
        <site name="ee_y" pos="0 0.1 0" size="0.005 .1" quat="0.707105 0.707108 0 0" rgba="0 1 0 0" type="cylinder" group="1" />
        <site name="ee_z" pos="0 0 0.1" size="0.005 .1" quat="1 0 0 0" rgba="0 0 1 0" type="cylinder" group="1" />
        <site name="grip_site_cylinder" pos="0 0 0" size="0.005 10" rgba="0 1 0 0.3" type="cylinder" group="1" />
      </body>
      <inertial pos="-0.00065489 -0.0018497 0.048028" mass="0.54156"
                diaginertia="0.00047106 0.00033072 0.00025642" />
      <geom type="mesh" contype="0" conaffinity="0" group="1" rgba="1 1 1 1" name="base_link_visual" mesh="xarm_gripper_base_link" />
      <geom type="mesh" group="0" rgba="1 1 1 1" name="base_link_collision" mesh="xarm_gripper_base_link" solref="0.01 0.25" />

      <body name="left_outer_knuckle" pos="0 0.035 0.059098">
        <inertial pos="0 0.021559 0.015181" mass="0.033618"
                  diaginertia="0.000019111 0.0000066256 0.000013185" />
        <joint name="left_driver_joint" axis="1 0 0" limited="true" range="0 0.85" armature="0.005" damping="0.1" frictionloss="1" solreflimit="0.005 1" />
        <geom type="mesh" contype="0" conaffinity="0" group="1" rgba="0.78 0.80 0.86 1" name="left_outer_knuckle_visual" mesh="xarm_gripper_left_outer_knuckle" />
        <geom type="mesh" group="0" rgba="0.78 0.80 0.86 1" name="left_outer_knuckle_collision" mesh="xarm_gripper_left_outer_knuckle" solref="0.01 0.25" />
        <body name="left_finger" pos="0 0.035465 0.042039">
          <inertial pos="0 -0.016413 0.029258" mass="0.048304"
                    diaginertia="0.000017493 0.000017225 0.0000051466" />
          <joint name="left_finger_joint" axis="-1 0 0" limited="true" range="0 0.85" armature="0.1" damping="0.01" frictionloss="1" solreflimit="0.005 1" />
          <geom type="mesh" contype="0" conaffinity="0" group="1" rgba="0.78 0.80 0.86 1" name="left_finger_visual" mesh="xarm_gripper_left_finger" />
          <geom size="0.015 0.002 0.0095" pos="0 -0.024003 0.032" type="box" group="0" name="left_finger_pad_1" friction="0.7" solimp="0.95 0.99 0.001" solref="0.004 1" mass="0" priority="1" rgba="0.0 0.1 0.7 1" />
          <geom size="0.015 0.002 0.0095" pos="0 -0.024003 0.050" type="box" group="0" name="left_finger_pad_2" friction="0.6" solimp="0.95 0.99 0.001" solref="0.004 1" mass="0" priority="1" rgba="0.0 0.5 0.5 1" />
        </body>
      </body>

      <body name="left_inner_knuckle" pos="0 0.02 0.074098">
        <inertial pos="0 0.022047 0.026133" mass="0.023013"
                  diaginertia="0.0000060949 0.0000060196 0.0000050786" />
        <joint name="left_inner_knuckle_joint" axis="1 0 0" limited="true" range="0 0.85" armature="0.1" stiffness="0.05" springref="2.62" damping="0.00125" frictionloss="1" solreflimit="0.005 1" />
        <geom type="mesh" contype="0" conaffinity="0" group="1" rgba="0.78 0.80 0.86 1" name="left_inner_knuckle_visual" mesh="xarm_gripper_left_inner_knuckle" />
        <geom type="mesh" group="0" rgba="0.78 0.80 0.86 1" name="left_inner_knuckle_collision" mesh="xarm_gripper_left_inner_knuckle" solref="0.01 0.25" />
      </body>

      <body name="right_outer_knuckle" pos="0 -0.035 0.059098">
        <inertial pos="0 -0.021559 0.015181" mass="0.033618"
                  diaginertia="0.000019111 0.0000066256 0.000013185" />
        <joint name="right_driver_joint" axis="-1 0 0" limited="true" range="0 0.85" armature="0.005" damping="0.1" frictionloss="1" solreflimit="0.005 1" />
        <geom type="mesh" contype="0" conaffinity="0" group="1" rgba="0.78 0.80 0.86 1" name="right_outer_knuckle_visual" mesh="xarm_gripper_right_outer_knuckle" />
        <geom type="mesh" group="0" rgba="0.78 0.80 0.86 1" name="right_outer_knuckle_collision" mesh="xarm_gripper_right_outer_knuckle" solref="0.01 0.25" />
        <body name="right_finger" pos="0 -0.035465 0.042039">
          <inertial pos="0 0.016413 0.029258" mass="0.048304"
                    diaginertia="0.000017493 0.000017225 0.0000051466" />
          <joint name="right_finger_joint" axis="1 0 0" limited="true" range="0 0.85" armature="0.1" damping="0.01" frictionloss="1" solreflimit="0.005 1" />
          <geom type="mesh" contype="0" conaffinity="0" group="1" rgba="0.78 0.80 0.86 1" name="right_finger_visual" mesh="xarm_gripper_right_finger" />
          <geom size="0.015 0.002 0.0095" pos="0 0.024003 0.032" type="box" group="0" name="right_finger_pad_1" friction="0.7" solimp="0.95 0.99 0.001" solref="0.004 1" mass="0" priority="1" rgba="0.0 0.1 0.7 1" />
          <geom size="0.015 0.002 0.0095" pos="0 0.024003 0.050" type="box" group="0" name="right_finger_pad_2" friction="0.6" solimp="0.95 0.99 0.001" solref="0.004 1" mass="0" priority="1" rgba="0.0 0.5 0.5 1" />
        </body>
      </body>

      <body name="right_inner_knuckle" pos="0 -0.02 0.074098">
        <inertial pos="0 -0.022047 0.026133" mass="0.023013"
                  diaginertia="0.0000060949 0.0000060196 0.0000050786" />
        <joint name="right_inner_knuckle_joint" axis="-1 0 0" limited="true" range="0 0.85" armature="0.1" stiffness="0.05" springref="2.62" damping="0.00125" frictionloss="1" solreflimit="0.005 1" />
        <geom type="mesh" contype="0" conaffinity="0" group="1" rgba="0.78 0.80 0.86 1" name="right_inner_knuckle_visual" mesh="xarm_gripper_right_inner_knuckle" />
        <geom type="mesh" group="0" rgba="0.78 0.80 0.86 1" name="right_inner_knuckle_collision" mesh="xarm_gripper_right_inner_knuckle" solref="0.01 0.25" />
      </body>
    </body>
  </worldbody>

  <contact>
    <exclude body1="right_inner_knuckle" body2="right_outer_knuckle" />
    <exclude body1="right_inner_knuckle" body2="right_finger" />
    <exclude body1="left_inner_knuckle" body2="left_outer_knuckle" />
    <exclude body1="left_inner_knuckle" body2="left_finger" />
    <exclude body1="left_inner_knuckle" body2="xarm_gripper_base_link" />
    <exclude body1="right_inner_knuckle" body2="xarm_gripper_base_link" />
    <exclude body1="left_outer_knuckle" body2="xarm_gripper_base_link" />
    <exclude body1="right_outer_knuckle" body2="xarm_gripper_base_link" />
  </contact>

  <tendon>
    <fixed name="xarm_gripper_split">
      <joint joint="right_driver_joint" coef="0.5" />
      <joint joint="left_driver_joint" coef="0.5" />
    </fixed>
  </tendon>

  <equality>
    <connect name="right_fourbar_loop" anchor="0 0.015 0.015" body1="right_finger" body2="right_inner_knuckle" solref="0.005 1" />
    <connect name="left_fourbar_loop" anchor="0 -0.015 0.015" body1="left_finger" body2="left_inner_knuckle" solref="0.005 1" />
    <joint name="driver_sync" joint1="left_driver_joint" joint2="right_driver_joint" polycoef="0 1 0 0 0" solref="0.005 1" />
  </equality>

  <actuator>
    <position name="finger" ctrllimited="true" kp="35" tendon="xarm_gripper_split" ctrlrange="0 0.85" />
  </actuator>

  <sensor>
    <force name="force_ee" site="ft_frame" />
    <torque name="torque_ee" site="ft_frame" />
  </sensor>
</mujoco>
